Updates were skipped successfully.
Updates were skipped successfully.
Updates were skipped successfully.
Cause exception while getting updates.
Traceback (most recent call last):
  File "/home/ubuntu/eng_bot/venv/lib/python3.10/site-packages/aiogram/dispatcher/dispatcher.py", line 381, in start_polling
    updates = await self.bot.get_updates(
  File "/home/ubuntu/eng_bot/venv/lib/python3.10/site-packages/aiogram/bot/bot.py", line 110, in get_updates
    result = await self.request(api.Methods.GET_UPDATES, payload)
  File "/home/ubuntu/eng_bot/venv/lib/python3.10/site-packages/aiogram/bot/base.py", line 231, in request
    return await api.make_request(await self.get_session(), self.server, self.__token, method, data, files,
  File "/home/ubuntu/eng_bot/venv/lib/python3.10/site-packages/aiogram/bot/api.py", line 140, in make_request
    return check_result(method, response.content_type, response.status, await response.text())
  File "/home/ubuntu/eng_bot/venv/lib/python3.10/site-packages/aiogram/bot/api.py", line 111, in check_result
    raise exceptions.RetryAfter(parameters.retry_after)
aiogram.utils.exceptions.RetryAfter: Flood control exceeded. Retry in 5 seconds.
Cause exception while getting updates.
Traceback (most recent call last):
  File "/home/ubuntu/eng_bot/venv/lib/python3.10/site-packages/aiogram/dispatcher/dispatcher.py", line 381, in start_polling
    updates = await self.bot.get_updates(
  File "/home/ubuntu/eng_bot/venv/lib/python3.10/site-packages/aiogram/bot/bot.py", line 110, in get_updates
    result = await self.request(api.Methods.GET_UPDATES, payload)
  File "/home/ubuntu/eng_bot/venv/lib/python3.10/site-packages/aiogram/bot/base.py", line 231, in request
    return await api.make_request(await self.get_session(), self.server, self.__token, method, data, files,
  File "/home/ubuntu/eng_bot/venv/lib/python3.10/site-packages/aiogram/bot/api.py", line 140, in make_request
    return check_result(method, response.content_type, response.status, await response.text())
  File "/home/ubuntu/eng_bot/venv/lib/python3.10/site-packages/aiogram/bot/api.py", line 111, in check_result
    raise exceptions.RetryAfter(parameters.retry_after)
aiogram.utils.exceptions.RetryAfter: Flood control exceeded. Retry in 5 seconds.
Task exception was never retrieved
future: <Task finished name='Task-16170' coro=<Dispatcher._process_polling_updates() done, defined at /home/ubuntu/eng_bot/venv/lib/python3.10/site-packages/aiogram/dispatcher/dispatcher.py:407> exception=OperationalError('no such table: id_532135878')>
Traceback (most recent call last):
  File "/home/ubuntu/eng_bot/venv/lib/python3.10/site-packages/aiogram/dispatcher/dispatcher.py", line 415, in _process_polling_updates
    for responses in itertools.chain.from_iterable(await self.process_updates(updates, fast)):
  File "/home/ubuntu/eng_bot/venv/lib/python3.10/site-packages/aiogram/dispatcher/dispatcher.py", line 235, in process_updates
    return await asyncio.gather(*tasks)
  File "/home/ubuntu/eng_bot/venv/lib/python3.10/site-packages/aiogram/dispatcher/handler.py", line 116, in notify
    response = await handler_obj.handler(*args, **partial_data)
  File "/home/ubuntu/eng_bot/venv/lib/python3.10/site-packages/aiogram/dispatcher/dispatcher.py", line 256, in process_update
    return await self.message_handlers.notify(update.message)
  File "/home/ubuntu/eng_bot/venv/lib/python3.10/site-packages/aiogram/dispatcher/handler.py", line 116, in notify
    response = await handler_obj.handler(*args, **partial_data)
  File "/home/ubuntu/eng_bot/handler/handlers.py", line 830, in replay_questions
    word_rus = len(data_base.select_data(word_rus))
  File "/home/ubuntu/eng_bot/DB/db2.py", line 74, in select_data
    cursor.execute(f"""SELECT {column_} FROM {self.id_user} WHERE {column_} is not Null """)
sqlite3.OperationalError: no such table: id_532135878
Task exception was never retrieved
future: <Task finished name='Task-16173' coro=<Dispatcher._process_polling_updates() done, defined at /home/ubuntu/eng_bot/venv/lib/python3.10/site-packages/aiogram/dispatcher/dispatcher.py:407> exception=OperationalError('no such table: id_532135878')>
Traceback (most recent call last):
  File "/home/ubuntu/eng_bot/venv/lib/python3.10/site-packages/aiogram/dispatcher/dispatcher.py", line 415, in _process_polling_updates
    for responses in itertools.chain.from_iterable(await self.process_updates(updates, fast)):
  File "/home/ubuntu/eng_bot/venv/lib/python3.10/site-packages/aiogram/dispatcher/dispatcher.py", line 235, in process_updates
    return await asyncio.gather(*tasks)
  File "/home/ubuntu/eng_bot/venv/lib/python3.10/site-packages/aiogram/dispatcher/handler.py", line 116, in notify
    response = await handler_obj.handler(*args, **partial_data)
  File "/home/ubuntu/eng_bot/venv/lib/python3.10/site-packages/aiogram/dispatcher/dispatcher.py", line 256, in process_update
    return await self.message_handlers.notify(update.message)
  File "/home/ubuntu/eng_bot/venv/lib/python3.10/site-packages/aiogram/dispatcher/handler.py", line 116, in notify
    response = await handler_obj.handler(*args, **partial_data)
  File "/home/ubuntu/eng_bot/handler/handlers.py", line 18, in add_word
    param_answer = data_base.select_data(param_answer_)[0][0]
  File "/home/ubuntu/eng_bot/DB/db2.py", line 74, in select_data
    cursor.execute(f"""SELECT {column_} FROM {self.id_user} WHERE {column_} is not Null """)
sqlite3.OperationalError: no such table: id_532135878
Task exception was never retrieved
future: <Task finished name='Task-16176' coro=<Dispatcher._process_polling_updates() done, defined at /home/ubuntu/eng_bot/venv/lib/python3.10/site-packages/aiogram/dispatcher/dispatcher.py:407> exception=OperationalError('no such table: id_532135878')>
Traceback (most recent call last):
  File "/home/ubuntu/eng_bot/venv/lib/python3.10/site-packages/aiogram/dispatcher/dispatcher.py", line 415, in _process_polling_updates
    for responses in itertools.chain.from_iterable(await self.process_updates(updates, fast)):
  File "/home/ubuntu/eng_bot/venv/lib/python3.10/site-packages/aiogram/dispatcher/dispatcher.py", line 235, in process_updates
    return await asyncio.gather(*tasks)
  File "/home/ubuntu/eng_bot/venv/lib/python3.10/site-packages/aiogram/dispatcher/handler.py", line 116, in notify
    response = await handler_obj.handler(*args, **partial_data)
  File "/home/ubuntu/eng_bot/venv/lib/python3.10/site-packages/aiogram/dispatcher/dispatcher.py", line 256, in process_update
    return await self.message_handlers.notify(update.message)
  File "/home/ubuntu/eng_bot/venv/lib/python3.10/site-packages/aiogram/dispatcher/handler.py", line 116, in notify
    response = await handler_obj.handler(*args, **partial_data)
  File "/home/ubuntu/eng_bot/handler/handlers.py", line 596, in user_settings
    param_answer = data_base.select_data(param_answer_)[0][0]
  File "/home/ubuntu/eng_bot/DB/db2.py", line 74, in select_data
    cursor.execute(f"""SELECT {column_} FROM {self.id_user} WHERE {column_} is not Null """)
sqlite3.OperationalError: no such table: id_532135878
Cause exception while getting updates.
Traceback (most recent call last):
  File "/home/ubuntu/eng_bot/venv/lib/python3.10/site-packages/aiogram/dispatcher/dispatcher.py", line 381, in start_polling
    updates = await self.bot.get_updates(
  File "/home/ubuntu/eng_bot/venv/lib/python3.10/site-packages/aiogram/bot/bot.py", line 110, in get_updates
    result = await self.request(api.Methods.GET_UPDATES, payload)
  File "/home/ubuntu/eng_bot/venv/lib/python3.10/site-packages/aiogram/bot/base.py", line 231, in request
    return await api.make_request(await self.get_session(), self.server, self.__token, method, data, files,
  File "/home/ubuntu/eng_bot/venv/lib/python3.10/site-packages/aiogram/bot/api.py", line 140, in make_request
    return check_result(method, response.content_type, response.status, await response.text())
  File "/home/ubuntu/eng_bot/venv/lib/python3.10/site-packages/aiogram/bot/api.py", line 111, in check_result
    raise exceptions.RetryAfter(parameters.retry_after)
aiogram.utils.exceptions.RetryAfter: Flood control exceeded. Retry in 5 seconds.
Cause exception while getting updates.
Traceback (most recent call last):
  File "/home/ubuntu/eng_bot/venv/lib/python3.10/site-packages/aiogram/dispatcher/dispatcher.py", line 381, in start_polling
    updates = await self.bot.get_updates(
  File "/home/ubuntu/eng_bot/venv/lib/python3.10/site-packages/aiogram/bot/bot.py", line 110, in get_updates
    result = await self.request(api.Methods.GET_UPDATES, payload)
  File "/home/ubuntu/eng_bot/venv/lib/python3.10/site-packages/aiogram/bot/base.py", line 231, in request
    return await api.make_request(await self.get_session(), self.server, self.__token, method, data, files,
  File "/home/ubuntu/eng_bot/venv/lib/python3.10/site-packages/aiogram/bot/api.py", line 140, in make_request
    return check_result(method, response.content_type, response.status, await response.text())
  File "/home/ubuntu/eng_bot/venv/lib/python3.10/site-packages/aiogram/bot/api.py", line 111, in check_result
    raise exceptions.RetryAfter(parameters.retry_after)
aiogram.utils.exceptions.RetryAfter: Flood control exceeded. Retry in 5 seconds.
Cause exception while getting updates.
Traceback (most recent call last):
  File "/home/ubuntu/eng_bot/venv/lib/python3.10/site-packages/aiogram/dispatcher/dispatcher.py", line 381, in start_polling
    updates = await self.bot.get_updates(
  File "/home/ubuntu/eng_bot/venv/lib/python3.10/site-packages/aiogram/bot/bot.py", line 110, in get_updates
    result = await self.request(api.Methods.GET_UPDATES, payload)
  File "/home/ubuntu/eng_bot/venv/lib/python3.10/site-packages/aiogram/bot/base.py", line 231, in request
    return await api.make_request(await self.get_session(), self.server, self.__token, method, data, files,
  File "/home/ubuntu/eng_bot/venv/lib/python3.10/site-packages/aiogram/bot/api.py", line 140, in make_request
    return check_result(method, response.content_type, response.status, await response.text())
  File "/home/ubuntu/eng_bot/venv/lib/python3.10/site-packages/aiogram/bot/api.py", line 128, in check_result
    raise exceptions.TelegramAPIError(description)
aiogram.utils.exceptions.TelegramAPIError: Bad Gateway
Cause exception while getting updates.
Traceback (most recent call last):
  File "/home/ubuntu/eng_bot/venv/lib/python3.10/site-packages/aiogram/dispatcher/dispatcher.py", line 381, in start_polling
    updates = await self.bot.get_updates(
  File "/home/ubuntu/eng_bot/venv/lib/python3.10/site-packages/aiogram/bot/bot.py", line 110, in get_updates
    result = await self.request(api.Methods.GET_UPDATES, payload)
  File "/home/ubuntu/eng_bot/venv/lib/python3.10/site-packages/aiogram/bot/base.py", line 231, in request
    return await api.make_request(await self.get_session(), self.server, self.__token, method, data, files,
  File "/home/ubuntu/eng_bot/venv/lib/python3.10/site-packages/aiogram/bot/api.py", line 140, in make_request
    return check_result(method, response.content_type, response.status, await response.text())
  File "/home/ubuntu/eng_bot/venv/lib/python3.10/site-packages/aiogram/bot/api.py", line 111, in check_result
    raise exceptions.RetryAfter(parameters.retry_after)
aiogram.utils.exceptions.RetryAfter: Flood control exceeded. Retry in 5 seconds.
Cause exception while getting updates.
Traceback (most recent call last):
  File "/home/ubuntu/eng_bot/venv/lib/python3.10/site-packages/aiogram/dispatcher/dispatcher.py", line 381, in start_polling
    updates = await self.bot.get_updates(
  File "/home/ubuntu/eng_bot/venv/lib/python3.10/site-packages/aiogram/bot/bot.py", line 110, in get_updates
    result = await self.request(api.Methods.GET_UPDATES, payload)
  File "/home/ubuntu/eng_bot/venv/lib/python3.10/site-packages/aiogram/bot/base.py", line 231, in request
    return await api.make_request(await self.get_session(), self.server, self.__token, method, data, files,
  File "/home/ubuntu/eng_bot/venv/lib/python3.10/site-packages/aiogram/bot/api.py", line 140, in make_request
    return check_result(method, response.content_type, response.status, await response.text())
  File "/home/ubuntu/eng_bot/venv/lib/python3.10/site-packages/aiogram/bot/api.py", line 111, in check_result
    raise exceptions.RetryAfter(parameters.retry_after)
aiogram.utils.exceptions.RetryAfter: Flood control exceeded. Retry in 5 seconds.
Cause exception while getting updates.
Traceback (most recent call last):
  File "/home/ubuntu/eng_bot/venv/lib/python3.10/site-packages/aiogram/dispatcher/dispatcher.py", line 381, in start_polling
    updates = await self.bot.get_updates(
  File "/home/ubuntu/eng_bot/venv/lib/python3.10/site-packages/aiogram/bot/bot.py", line 110, in get_updates
    result = await self.request(api.Methods.GET_UPDATES, payload)
  File "/home/ubuntu/eng_bot/venv/lib/python3.10/site-packages/aiogram/bot/base.py", line 231, in request
    return await api.make_request(await self.get_session(), self.server, self.__token, method, data, files,
  File "/home/ubuntu/eng_bot/venv/lib/python3.10/site-packages/aiogram/bot/api.py", line 140, in make_request
    return check_result(method, response.content_type, response.status, await response.text())
  File "/home/ubuntu/eng_bot/venv/lib/python3.10/site-packages/aiogram/bot/api.py", line 111, in check_result
    raise exceptions.RetryAfter(parameters.retry_after)
aiogram.utils.exceptions.RetryAfter: Flood control exceeded. Retry in 5 seconds.
Cause exception while getting updates.
Traceback (most recent call last):
  File "/home/ubuntu/eng_bot/venv/lib/python3.10/site-packages/aiogram/dispatcher/dispatcher.py", line 381, in start_polling
    updates = await self.bot.get_updates(
  File "/home/ubuntu/eng_bot/venv/lib/python3.10/site-packages/aiogram/bot/bot.py", line 110, in get_updates
    result = await self.request(api.Methods.GET_UPDATES, payload)
  File "/home/ubuntu/eng_bot/venv/lib/python3.10/site-packages/aiogram/bot/base.py", line 231, in request
    return await api.make_request(await self.get_session(), self.server, self.__token, method, data, files,
  File "/home/ubuntu/eng_bot/venv/lib/python3.10/site-packages/aiogram/bot/api.py", line 140, in make_request
    return check_result(method, response.content_type, response.status, await response.text())
  File "/home/ubuntu/eng_bot/venv/lib/python3.10/site-packages/aiogram/bot/api.py", line 111, in check_result
    raise exceptions.RetryAfter(parameters.retry_after)
aiogram.utils.exceptions.RetryAfter: Flood control exceeded. Retry in 5 seconds.
Traceback (most recent call last):
  File "/home/ubuntu/eng_bot/main.py", line 1, in <module>
    from aiogram.utils import executor
ModuleNotFoundError: No module named 'aiogram'
Traceback (most recent call last):
  File "/home/ubuntu/eng_bot/main.py", line 1, in <module>
    from aiogram.utils import executor
ModuleNotFoundError: No module named 'aiogram'
Traceback (most recent call last):
  File "/home/ubuntu/eng_bot/main.py", line 1, in <module>
    from aiogram.utils import executor
ModuleNotFoundError: No module named 'aiogram'
Updates were skipped successfully.
Task exception was never retrieved
future: <Task finished name='Task-9' coro=<Dispatcher._process_polling_updates() done, defined at /home/ubuntu/eng_bot/venv/lib/python3.10/site-packages/aiogram/dispatcher/dispatcher.py:407> exception=KeyError('param_questions')>
Traceback (most recent call last):
  File "/home/ubuntu/eng_bot/venv/lib/python3.10/site-packages/aiogram/dispatcher/dispatcher.py", line 415, in _process_polling_updates
    for responses in itertools.chain.from_iterable(await self.process_updates(updates, fast)):
  File "/home/ubuntu/eng_bot/venv/lib/python3.10/site-packages/aiogram/dispatcher/dispatcher.py", line 235, in process_updates
    return await asyncio.gather(*tasks)
  File "/home/ubuntu/eng_bot/venv/lib/python3.10/site-packages/aiogram/dispatcher/handler.py", line 116, in notify
    response = await handler_obj.handler(*args, **partial_data)
  File "/home/ubuntu/eng_bot/venv/lib/python3.10/site-packages/aiogram/dispatcher/dispatcher.py", line 256, in process_update
    return await self.message_handlers.notify(update.message)
  File "/home/ubuntu/eng_bot/venv/lib/python3.10/site-packages/aiogram/dispatcher/handler.py", line 116, in notify
    response = await handler_obj.handler(*args, **partial_data)
  File "/home/ubuntu/eng_bot/handler/handlers.py", line 375, in question_test
    param_questions = int(state_data["param_questions"])
KeyError: 'param_questions'
Cause exception while getting updates.
Traceback (most recent call last):
  File "/home/ubuntu/eng_bot/venv/lib/python3.10/site-packages/aiogram/dispatcher/dispatcher.py", line 381, in start_polling
    updates = await self.bot.get_updates(
  File "/home/ubuntu/eng_bot/venv/lib/python3.10/site-packages/aiogram/bot/bot.py", line 110, in get_updates
    result = await self.request(api.Methods.GET_UPDATES, payload)
  File "/home/ubuntu/eng_bot/venv/lib/python3.10/site-packages/aiogram/bot/base.py", line 231, in request
    return await api.make_request(await self.get_session(), self.server, self.__token, method, data, files,
  File "/home/ubuntu/eng_bot/venv/lib/python3.10/site-packages/aiogram/bot/api.py", line 140, in make_request
    return check_result(method, response.content_type, response.status, await response.text())
  File "/home/ubuntu/eng_bot/venv/lib/python3.10/site-packages/aiogram/bot/api.py", line 111, in check_result
    raise exceptions.RetryAfter(parameters.retry_after)
aiogram.utils.exceptions.RetryAfter: Flood control exceeded. Retry in 5 seconds.
Task exception was never retrieved
future: <Task finished name='Task-1112' coro=<Dispatcher._process_polling_updates() done, defined at /home/ubuntu/eng_bot/venv/lib/python3.10/site-packages/aiogram/dispatcher/dispatcher.py:407> exception=OperationalError('no such table: id_532135878')>
Traceback (most recent call last):
  File "/home/ubuntu/eng_bot/venv/lib/python3.10/site-packages/aiogram/dispatcher/dispatcher.py", line 415, in _process_polling_updates
    for responses in itertools.chain.from_iterable(await self.process_updates(updates, fast)):
  File "/home/ubuntu/eng_bot/venv/lib/python3.10/site-packages/aiogram/dispatcher/dispatcher.py", line 235, in process_updates
    return await asyncio.gather(*tasks)
  File "/home/ubuntu/eng_bot/venv/lib/python3.10/site-packages/aiogram/dispatcher/handler.py", line 116, in notify
    response = await handler_obj.handler(*args, **partial_data)
  File "/home/ubuntu/eng_bot/venv/lib/python3.10/site-packages/aiogram/dispatcher/dispatcher.py", line 256, in process_update
    return await self.message_handlers.notify(update.message)
  File "/home/ubuntu/eng_bot/venv/lib/python3.10/site-packages/aiogram/dispatcher/handler.py", line 116, in notify
    response = await handler_obj.handler(*args, **partial_data)
  File "/home/ubuntu/eng_bot/handler/handlers.py", line 19, in add_word
    mode_questions = json.loads(data_base.select_data_(
  File "/home/ubuntu/eng_bot/DB/db2.py", line 127, in select_data_
    cursor.execute(f"""SELECT {column_} FROM {self.id_user} WHERE {where_clmn} = '{where_data}' """)
sqlite3.OperationalError: no such table: id_532135878
Cause exception while getting updates.
Traceback (most recent call last):
  File "/home/ubuntu/eng_bot/venv/lib/python3.10/site-packages/aiohttp/connector.py", line 986, in _wrap_create_connection
    return await self._loop.create_connection(*args, **kwargs)  # type: ignore[return-value]  # noqa
  File "/usr/lib/python3.10/asyncio/base_events.py", line 1064, in create_connection
    raise exceptions[0]
  File "/usr/lib/python3.10/asyncio/base_events.py", line 1049, in create_connection
    sock = await self._connect_sock(
  File "/usr/lib/python3.10/asyncio/base_events.py", line 960, in _connect_sock
    await self.sock_connect(sock, address)
  File "/usr/lib/python3.10/asyncio/selector_events.py", line 500, in sock_connect
    return await fut
  File "/usr/lib/python3.10/asyncio/selector_events.py", line 505, in _sock_connect
    sock.connect(address)
OSError: [Errno 101] Network is unreachable

The above exception was the direct cause of the following exception:

Traceback (most recent call last):
  File "/home/ubuntu/eng_bot/venv/lib/python3.10/site-packages/aiogram/bot/api.py", line 139, in make_request
    async with session.post(url, data=req, **kwargs) as response:
  File "/home/ubuntu/eng_bot/venv/lib/python3.10/site-packages/aiohttp/client.py", line 1138, in __aenter__
    self._resp = await self._coro
  File "/home/ubuntu/eng_bot/venv/lib/python3.10/site-packages/aiohttp/client.py", line 535, in _request
    conn = await self._connector.connect(
  File "/home/ubuntu/eng_bot/venv/lib/python3.10/site-packages/aiohttp/connector.py", line 542, in connect
    proto = await self._create_connection(req, traces, timeout)
  File "/home/ubuntu/eng_bot/venv/lib/python3.10/site-packages/aiohttp/connector.py", line 907, in _create_connection
    _, proto = await self._create_direct_connection(req, traces, timeout)
  File "/home/ubuntu/eng_bot/venv/lib/python3.10/site-packages/aiohttp/connector.py", line 1206, in _create_direct_connection
    raise last_exc
  File "/home/ubuntu/eng_bot/venv/lib/python3.10/site-packages/aiohttp/connector.py", line 1175, in _create_direct_connection
    transp, proto = await self._wrap_create_connection(
  File "/home/ubuntu/eng_bot/venv/lib/python3.10/site-packages/aiohttp/connector.py", line 992, in _wrap_create_connection
    raise client_error(req.connection_key, exc) from exc
aiohttp.client_exceptions.ClientConnectorError: Cannot connect to host api.telegram.org:443 ssl:default [Network is unreachable]

During handling of the above exception, another exception occurred:

Traceback (most recent call last):
  File "/home/ubuntu/eng_bot/venv/lib/python3.10/site-packages/aiogram/dispatcher/dispatcher.py", line 381, in start_polling
    updates = await self.bot.get_updates(
  File "/home/ubuntu/eng_bot/venv/lib/python3.10/site-packages/aiogram/bot/bot.py", line 110, in get_updates
    result = await self.request(api.Methods.GET_UPDATES, payload)
  File "/home/ubuntu/eng_bot/venv/lib/python3.10/site-packages/aiogram/bot/base.py", line 231, in request
    return await api.make_request(await self.get_session(), self.server, self.__token, method, data, files,
  File "/home/ubuntu/eng_bot/venv/lib/python3.10/site-packages/aiogram/bot/api.py", line 142, in make_request
    raise exceptions.NetworkError(f"aiohttp client throws an error: {e.__class__.__name__}: {e}")
aiogram.utils.exceptions.NetworkError: Aiohttp client throws an error: ClientConnectorError: Cannot connect to host api.telegram.org:443 ssl:default [Network is unreachable]
Cause exception while getting updates.
Traceback (most recent call last):
  File "/home/ubuntu/eng_bot/venv/lib/python3.10/site-packages/aiogram/dispatcher/dispatcher.py", line 381, in start_polling
    updates = await self.bot.get_updates(
  File "/home/ubuntu/eng_bot/venv/lib/python3.10/site-packages/aiogram/bot/bot.py", line 110, in get_updates
    result = await self.request(api.Methods.GET_UPDATES, payload)
  File "/home/ubuntu/eng_bot/venv/lib/python3.10/site-packages/aiogram/bot/base.py", line 231, in request
    return await api.make_request(await self.get_session(), self.server, self.__token, method, data, files,
  File "/home/ubuntu/eng_bot/venv/lib/python3.10/site-packages/aiogram/bot/api.py", line 140, in make_request
    return check_result(method, response.content_type, response.status, await response.text())
  File "/home/ubuntu/eng_bot/venv/lib/python3.10/site-packages/aiogram/bot/api.py", line 128, in check_result
    raise exceptions.TelegramAPIError(description)
aiogram.utils.exceptions.TelegramAPIError: Bad Gateway
Cause exception while getting updates.
Traceback (most recent call last):
  File "/home/ubuntu/eng_bot/venv/lib/python3.10/site-packages/aiogram/dispatcher/dispatcher.py", line 381, in start_polling
    updates = await self.bot.get_updates(
  File "/home/ubuntu/eng_bot/venv/lib/python3.10/site-packages/aiogram/bot/bot.py", line 110, in get_updates
    result = await self.request(api.Methods.GET_UPDATES, payload)
  File "/home/ubuntu/eng_bot/venv/lib/python3.10/site-packages/aiogram/bot/base.py", line 231, in request
    return await api.make_request(await self.get_session(), self.server, self.__token, method, data, files,
  File "/home/ubuntu/eng_bot/venv/lib/python3.10/site-packages/aiogram/bot/api.py", line 140, in make_request
    return check_result(method, response.content_type, response.status, await response.text())
  File "/home/ubuntu/eng_bot/venv/lib/python3.10/site-packages/aiogram/bot/api.py", line 111, in check_result
    raise exceptions.RetryAfter(parameters.retry_after)
aiogram.utils.exceptions.RetryAfter: Flood control exceeded. Retry in 5 seconds.
Cause exception while getting updates.
Traceback (most recent call last):
  File "/home/ubuntu/eng_bot/venv/lib/python3.10/site-packages/aiogram/dispatcher/dispatcher.py", line 381, in start_polling
    updates = await self.bot.get_updates(
  File "/home/ubuntu/eng_bot/venv/lib/python3.10/site-packages/aiogram/bot/bot.py", line 110, in get_updates
    result = await self.request(api.Methods.GET_UPDATES, payload)
  File "/home/ubuntu/eng_bot/venv/lib/python3.10/site-packages/aiogram/bot/base.py", line 231, in request
    return await api.make_request(await self.get_session(), self.server, self.__token, method, data, files,
  File "/home/ubuntu/eng_bot/venv/lib/python3.10/site-packages/aiogram/bot/api.py", line 140, in make_request
    return check_result(method, response.content_type, response.status, await response.text())
  File "/home/ubuntu/eng_bot/venv/lib/python3.10/site-packages/aiogram/bot/api.py", line 111, in check_result
    raise exceptions.RetryAfter(parameters.retry_after)
aiogram.utils.exceptions.RetryAfter: Flood control exceeded. Retry in 5 seconds.
Cause exception while getting updates.
Traceback (most recent call last):
  File "/home/ubuntu/eng_bot/venv/lib/python3.10/site-packages/aiogram/dispatcher/dispatcher.py", line 381, in start_polling
    updates = await self.bot.get_updates(
  File "/home/ubuntu/eng_bot/venv/lib/python3.10/site-packages/aiogram/bot/bot.py", line 110, in get_updates
    result = await self.request(api.Methods.GET_UPDATES, payload)
  File "/home/ubuntu/eng_bot/venv/lib/python3.10/site-packages/aiogram/bot/base.py", line 231, in request
    return await api.make_request(await self.get_session(), self.server, self.__token, method, data, files,
  File "/home/ubuntu/eng_bot/venv/lib/python3.10/site-packages/aiogram/bot/api.py", line 140, in make_request
    return check_result(method, response.content_type, response.status, await response.text())
  File "/home/ubuntu/eng_bot/venv/lib/python3.10/site-packages/aiogram/bot/api.py", line 111, in check_result
    raise exceptions.RetryAfter(parameters.retry_after)
aiogram.utils.exceptions.RetryAfter: Flood control exceeded. Retry in 5 seconds.
Cause exception while getting updates.
Traceback (most recent call last):
  File "/home/ubuntu/eng_bot/venv/lib/python3.10/site-packages/aiogram/dispatcher/dispatcher.py", line 381, in start_polling
    updates = await self.bot.get_updates(
  File "/home/ubuntu/eng_bot/venv/lib/python3.10/site-packages/aiogram/bot/bot.py", line 110, in get_updates
    result = await self.request(api.Methods.GET_UPDATES, payload)
  File "/home/ubuntu/eng_bot/venv/lib/python3.10/site-packages/aiogram/bot/base.py", line 231, in request
    return await api.make_request(await self.get_session(), self.server, self.__token, method, data, files,
  File "/home/ubuntu/eng_bot/venv/lib/python3.10/site-packages/aiogram/bot/api.py", line 140, in make_request
    return check_result(method, response.content_type, response.status, await response.text())
  File "/home/ubuntu/eng_bot/venv/lib/python3.10/site-packages/aiogram/bot/api.py", line 128, in check_result
    raise exceptions.TelegramAPIError(description)
aiogram.utils.exceptions.TelegramAPIError: Bad Gateway
