Updates were skipped successfully.
Updates were skipped successfully.
Updates were skipped successfully.
Cause exception while getting updates.
Traceback (most recent call last):
  File "/home/ubuntu/eng_bot/venv/lib/python3.10/site-packages/aiogram/dispatcher/dispatcher.py", line 381, in start_polling
    updates = await self.bot.get_updates(
  File "/home/ubuntu/eng_bot/venv/lib/python3.10/site-packages/aiogram/bot/bot.py", line 110, in get_updates
    result = await self.request(api.Methods.GET_UPDATES, payload)
  File "/home/ubuntu/eng_bot/venv/lib/python3.10/site-packages/aiogram/bot/base.py", line 231, in request
    return await api.make_request(await self.get_session(), self.server, self.__token, method, data, files,
  File "/home/ubuntu/eng_bot/venv/lib/python3.10/site-packages/aiogram/bot/api.py", line 140, in make_request
    return check_result(method, response.content_type, response.status, await response.text())
  File "/home/ubuntu/eng_bot/venv/lib/python3.10/site-packages/aiogram/bot/api.py", line 111, in check_result
    raise exceptions.RetryAfter(parameters.retry_after)
aiogram.utils.exceptions.RetryAfter: Flood control exceeded. Retry in 5 seconds.
Cause exception while getting updates.
Traceback (most recent call last):
  File "/home/ubuntu/eng_bot/venv/lib/python3.10/site-packages/aiogram/dispatcher/dispatcher.py", line 381, in start_polling
    updates = await self.bot.get_updates(
  File "/home/ubuntu/eng_bot/venv/lib/python3.10/site-packages/aiogram/bot/bot.py", line 110, in get_updates
    result = await self.request(api.Methods.GET_UPDATES, payload)
  File "/home/ubuntu/eng_bot/venv/lib/python3.10/site-packages/aiogram/bot/base.py", line 231, in request
    return await api.make_request(await self.get_session(), self.server, self.__token, method, data, files,
  File "/home/ubuntu/eng_bot/venv/lib/python3.10/site-packages/aiogram/bot/api.py", line 140, in make_request
    return check_result(method, response.content_type, response.status, await response.text())
  File "/home/ubuntu/eng_bot/venv/lib/python3.10/site-packages/aiogram/bot/api.py", line 111, in check_result
    raise exceptions.RetryAfter(parameters.retry_after)
aiogram.utils.exceptions.RetryAfter: Flood control exceeded. Retry in 5 seconds.
Task exception was never retrieved
future: <Task finished name='Task-16170' coro=<Dispatcher._process_polling_updates() done, defined at /home/ubuntu/eng_bot/venv/lib/python3.10/site-packages/aiogram/dispatcher/dispatcher.py:407> exception=OperationalError('no such table: id_532135878')>
Traceback (most recent call last):
  File "/home/ubuntu/eng_bot/venv/lib/python3.10/site-packages/aiogram/dispatcher/dispatcher.py", line 415, in _process_polling_updates
    for responses in itertools.chain.from_iterable(await self.process_updates(updates, fast)):
  File "/home/ubuntu/eng_bot/venv/lib/python3.10/site-packages/aiogram/dispatcher/dispatcher.py", line 235, in process_updates
    return await asyncio.gather(*tasks)
  File "/home/ubuntu/eng_bot/venv/lib/python3.10/site-packages/aiogram/dispatcher/handler.py", line 116, in notify
    response = await handler_obj.handler(*args, **partial_data)
  File "/home/ubuntu/eng_bot/venv/lib/python3.10/site-packages/aiogram/dispatcher/dispatcher.py", line 256, in process_update
    return await self.message_handlers.notify(update.message)
  File "/home/ubuntu/eng_bot/venv/lib/python3.10/site-packages/aiogram/dispatcher/handler.py", line 116, in notify
    response = await handler_obj.handler(*args, **partial_data)
  File "/home/ubuntu/eng_bot/handler/handlers.py", line 830, in replay_questions
    word_rus = len(data_base.select_data(word_rus))
  File "/home/ubuntu/eng_bot/DB/db2.py", line 74, in select_data
    cursor.execute(f"""SELECT {column_} FROM {self.id_user} WHERE {column_} is not Null """)
sqlite3.OperationalError: no such table: id_532135878
Task exception was never retrieved
future: <Task finished name='Task-16173' coro=<Dispatcher._process_polling_updates() done, defined at /home/ubuntu/eng_bot/venv/lib/python3.10/site-packages/aiogram/dispatcher/dispatcher.py:407> exception=OperationalError('no such table: id_532135878')>
Traceback (most recent call last):
  File "/home/ubuntu/eng_bot/venv/lib/python3.10/site-packages/aiogram/dispatcher/dispatcher.py", line 415, in _process_polling_updates
    for responses in itertools.chain.from_iterable(await self.process_updates(updates, fast)):
  File "/home/ubuntu/eng_bot/venv/lib/python3.10/site-packages/aiogram/dispatcher/dispatcher.py", line 235, in process_updates
    return await asyncio.gather(*tasks)
  File "/home/ubuntu/eng_bot/venv/lib/python3.10/site-packages/aiogram/dispatcher/handler.py", line 116, in notify
    response = await handler_obj.handler(*args, **partial_data)
  File "/home/ubuntu/eng_bot/venv/lib/python3.10/site-packages/aiogram/dispatcher/dispatcher.py", line 256, in process_update
    return await self.message_handlers.notify(update.message)
  File "/home/ubuntu/eng_bot/venv/lib/python3.10/site-packages/aiogram/dispatcher/handler.py", line 116, in notify
    response = await handler_obj.handler(*args, **partial_data)
  File "/home/ubuntu/eng_bot/handler/handlers.py", line 18, in add_word
    param_answer = data_base.select_data(param_answer_)[0][0]
  File "/home/ubuntu/eng_bot/DB/db2.py", line 74, in select_data
    cursor.execute(f"""SELECT {column_} FROM {self.id_user} WHERE {column_} is not Null """)
sqlite3.OperationalError: no such table: id_532135878
Task exception was never retrieved
future: <Task finished name='Task-16176' coro=<Dispatcher._process_polling_updates() done, defined at /home/ubuntu/eng_bot/venv/lib/python3.10/site-packages/aiogram/dispatcher/dispatcher.py:407> exception=OperationalError('no such table: id_532135878')>
Traceback (most recent call last):
  File "/home/ubuntu/eng_bot/venv/lib/python3.10/site-packages/aiogram/dispatcher/dispatcher.py", line 415, in _process_polling_updates
    for responses in itertools.chain.from_iterable(await self.process_updates(updates, fast)):
  File "/home/ubuntu/eng_bot/venv/lib/python3.10/site-packages/aiogram/dispatcher/dispatcher.py", line 235, in process_updates
    return await asyncio.gather(*tasks)
  File "/home/ubuntu/eng_bot/venv/lib/python3.10/site-packages/aiogram/dispatcher/handler.py", line 116, in notify
    response = await handler_obj.handler(*args, **partial_data)
  File "/home/ubuntu/eng_bot/venv/lib/python3.10/site-packages/aiogram/dispatcher/dispatcher.py", line 256, in process_update
    return await self.message_handlers.notify(update.message)
  File "/home/ubuntu/eng_bot/venv/lib/python3.10/site-packages/aiogram/dispatcher/handler.py", line 116, in notify
    response = await handler_obj.handler(*args, **partial_data)
  File "/home/ubuntu/eng_bot/handler/handlers.py", line 596, in user_settings
    param_answer = data_base.select_data(param_answer_)[0][0]
  File "/home/ubuntu/eng_bot/DB/db2.py", line 74, in select_data
    cursor.execute(f"""SELECT {column_} FROM {self.id_user} WHERE {column_} is not Null """)
sqlite3.OperationalError: no such table: id_532135878
Cause exception while getting updates.
Traceback (most recent call last):
  File "/home/ubuntu/eng_bot/venv/lib/python3.10/site-packages/aiogram/dispatcher/dispatcher.py", line 381, in start_polling
    updates = await self.bot.get_updates(
  File "/home/ubuntu/eng_bot/venv/lib/python3.10/site-packages/aiogram/bot/bot.py", line 110, in get_updates
    result = await self.request(api.Methods.GET_UPDATES, payload)
  File "/home/ubuntu/eng_bot/venv/lib/python3.10/site-packages/aiogram/bot/base.py", line 231, in request
    return await api.make_request(await self.get_session(), self.server, self.__token, method, data, files,
  File "/home/ubuntu/eng_bot/venv/lib/python3.10/site-packages/aiogram/bot/api.py", line 140, in make_request
    return check_result(method, response.content_type, response.status, await response.text())
  File "/home/ubuntu/eng_bot/venv/lib/python3.10/site-packages/aiogram/bot/api.py", line 111, in check_result
    raise exceptions.RetryAfter(parameters.retry_after)
aiogram.utils.exceptions.RetryAfter: Flood control exceeded. Retry in 5 seconds.
Cause exception while getting updates.
Traceback (most recent call last):
  File "/home/ubuntu/eng_bot/venv/lib/python3.10/site-packages/aiogram/dispatcher/dispatcher.py", line 381, in start_polling
    updates = await self.bot.get_updates(
  File "/home/ubuntu/eng_bot/venv/lib/python3.10/site-packages/aiogram/bot/bot.py", line 110, in get_updates
    result = await self.request(api.Methods.GET_UPDATES, payload)
  File "/home/ubuntu/eng_bot/venv/lib/python3.10/site-packages/aiogram/bot/base.py", line 231, in request
    return await api.make_request(await self.get_session(), self.server, self.__token, method, data, files,
  File "/home/ubuntu/eng_bot/venv/lib/python3.10/site-packages/aiogram/bot/api.py", line 140, in make_request
    return check_result(method, response.content_type, response.status, await response.text())
  File "/home/ubuntu/eng_bot/venv/lib/python3.10/site-packages/aiogram/bot/api.py", line 111, in check_result
    raise exceptions.RetryAfter(parameters.retry_after)
aiogram.utils.exceptions.RetryAfter: Flood control exceeded. Retry in 5 seconds.
